<?xml version="1.0"?>
<robot name="parobot">

  <!-- ====================== BASE ====================== -->
  <link name="base_link">
    <inertial>
      <origin xyz="0 0 0" rpy="0 0 0"/>
      <mass value="5.0"/>
      <inertia
        ixx="0.1" ixy="0.0" ixz="0.0"
        iyy="0.1" iyz="0.0"
        izz="0.1"/>
    </inertial>

    <visual>
      <origin xyz="0 0 0.1" rpy="0 0 0"/>
      <geometry>
        <box size="0.4 0.3 0.2"/>
      </geometry>
      <material name="blue">
        <color rgba="0.1 0.3 0.8 1.0"/>
      </material>
    </visual>

    <collision>
      <origin xyz="0 0 0.1" rpy="0 0 0"/>
      <geometry>
        <box size="0.4 0.3 0.2"/>
      </geometry>
    </collision>
  </link>

  <!-- ====================== LEFT WHEEL ====================== -->
  <link name="left_wheel">
    <inertial>
      <origin xyz="0 0 0" rpy="0 0 0"/>
      <mass value="0.5"/>
      <inertia
        ixx="0.01" ixy="0.0" ixz="0.0"
        iyy="0.01" iyz="0.0"
        izz="0.01"/>
    </inertial>

    <visual>
      <origin xyz="0 0 0" rpy="1.5708 0 0"/>
      <geometry>
        <cylinder radius="0.06" length="0.03"/>
      </geometry>
      <material name="black">
        <color rgba="0.05 0.05 0.05 1.0"/>
      </material>
    </visual>

    <collision>
      <origin xyz="0 0 0" rpy="1.5708 0 0"/>
      <geometry>
        <cylinder radius="0.06" length="0.03"/>
      </geometry>
    </collision>
  </link>

  <!-- ====================== RIGHT WHEEL ====================== -->
  <link name="right_wheel">
    <inertial>
      <origin xyz="0 0 0" rpy="0 0 0"/>
      <mass value="0.5"/>
      <inertia
        ixx="0.01" ixy="0.0" ixz="0.0"
        iyy="0.01" iyz="0.0"
        izz="0.01"/>
    </inertial>

    <visual>
      <origin xyz="0 0 0" rpy="1.5708 0 0"/>
      <geometry>
        <cylinder radius="0.06" length="0.03"/>
      </geometry>
      <material name="black">
        <color rgba="0.05 0.05 0.05 1.0"/>
      </material>
    </visual>

    <collision>
      <origin xyz="0 0 0" rpy="1.5708 0 0"/>
      <geometry>
        <cylinder radius="0.06" length="0.03"/>
      </geometry>
    </collision>
  </link>

  <!-- ====================== LIDAR LINK ====================== -->
  <link name="laser_link">
    <inertial>
      <origin xyz="0 0 0" rpy="0 0 0"/>
      <mass value="0.1"/>
      <inertia
        ixx="1e-4" ixy="0.0" ixz="0.0"
        iyy="1e-4" iyz="0.0"
        izz="1e-4"/>
    </inertial>

    <visual>
      <origin xyz="0.15 0 0.18" rpy="0 0 0"/>
      <geometry>
        <cylinder radius="0.03" length="0.02"/>
      </geometry>
      <material name="grey">
        <color rgba="0.6 0.6 0.6 1.0"/>
      </material>
    </visual>

    <collision>
      <origin xyz="0.15 0 0.18" rpy="0 0 0"/>
      <geometry>
        <cylinder radius="0.03" length="0.02"/>
      </geometry>
    </collision>
  </link>

  <!-- ====================== JOINTS ====================== -->

  <joint name="left_wheel_joint" type="continuous">
    <parent link="base_link"/>
    <child link="left_wheel"/>
    <origin xyz="0 0.15 0.06" rpy="0 0 0"/>
    <axis xyz="0 1 0"/>
  </joint>

  <joint name="right_wheel_joint" type="continuous">
    <parent link="base_link"/>
    <child link="right_wheel"/>
    <origin xyz="0 -0.15 0.06" rpy="0 0 0"/>
    <axis xyz="0 1 0"/>
  </joint>

  <joint name="laser_joint" type="fixed">
    <parent link="base_link"/>
    <child link="laser_link"/>
    <origin xyz="0.15 0 0.18" rpy="0 0 0"/>
  </joint>

</robot>
